<?xml version="1.0" ?>
<mujoco model="sharpa hand setup">
  <compiler angle="radian" autolimits="true" assetdir="assets" meshdir="assets" texturedir="assets"/>
  <visual>
    <headlight diffuse="0.6 0.6 0.6" ambient="0.3 0.3 0.3" specular="0 0 0"/>
    <rgba haze="0.15 0.25 0.35 1"/>
    <global azimuth="150" elevation="-20" offwidth="1280" offheight="1024"/>
  </visual>
  <asset>
    <texture type="skybox" builtin="gradient" rgb1="0.9 0.7 0.9" rgb2="0.94 0.97 0.97" width="512" height="3072"/>
    <texture type="2d" name="groundplane" builtin="checker" mark="edge" rgb1="0.2 0.3 0.4" rgb2="0.1 0.2 0.3" markrgb="0.8 0.8 0.8" width="300" height="300"/>
    <material name="groundplane" texture="groundplane" texuniform="true" texrepeat="5 5" reflectance="0.2"/>
    <material name="concrete-slab-concrete" rgba="0.8 0.8 0.8 1" shininess="0.5"/>
    <mesh name="right_hand_C_MC_visual" file="sharpa_hand/right_hand_C_MC_visual_.STL"/>
    <mesh name="right_hand_C_MC" file="sharpa_hand/right_hand_C_MC.STL"/>
    <mesh name="right_thumb_CMC_VL_visual" file="sharpa_hand/right_thumb_CMC_VL_visual.STL"/>
    <mesh name="right_thumb_MC_visual" file="sharpa_hand/right_thumb_MC_visual.STL"/>
    <mesh name="right_thumb_MC" file="sharpa_hand/right_thumb_MC.STL"/>
    <mesh name="right_thumb_MCP_VL_visual" file="sharpa_hand/right_thumb_MCP_VL_visual.STL"/>
    <mesh name="right_thumb_PP_visual" file="sharpa_hand/right_thumb_PP_visual.STL"/>
    <mesh name="right_thumb_PP" file="sharpa_hand/right_thumb_PP.STL"/>
    <mesh name="right_thumb_DP_visual" file="sharpa_hand/right_thumb_DP_visual.STL"/>
    <mesh name="right_thumb_DP" file="sharpa_hand/right_thumb_DP.STL"/>
    <mesh name="thumb_elastomer" file="sharpa_hand/thumb_elastomer.STL"/>
    <mesh name="right_MCP_VL_visual" file="sharpa_hand/right_MCP_VL_visual.STL"/>
    <mesh name="MCP_VL" file="sharpa_hand/MCP_VL.STL"/>
    <mesh name="right_PP_visual" file="sharpa_hand/right_PP_visual.STL"/>
    <mesh name="right_PP" file="sharpa_hand/right_PP.STL"/>
    <mesh name="right_MP_visual" file="sharpa_hand/right_MP_visual.STL"/>
    <mesh name="right_MP" file="sharpa_hand/right_MP.STL"/>
    <mesh name="right_DP_visual" file="sharpa_hand/right_DP_visual.STL"/>
    <mesh name="right_DP" file="sharpa_hand/right_DP.STL"/>
    <mesh name="elastomer" file="sharpa_hand/elastomer.STL"/>
    <mesh name="right_pinky_MC_visual" file="sharpa_hand/right_pinky_MC_visual.STL"/>
    <mesh name="right_pinky_MC" file="sharpa_hand/right_pinky_MC.STL"/>
    <mesh name="left_hand_C_MC_visual" file="sharpa_hand/left_hand_C_MC_visual_.STL"/>
    <mesh name="left_hand_C_MC" file="sharpa_hand/left_hand_C_MC.STL"/>
    <mesh name="left_thumb_CMC_VL_visual" file="sharpa_hand/left_thumb_CMC_VL.STL"/>
    <mesh name="left_thumb_MC_visual" file="sharpa_hand/left_thumb_MC_visual.STL"/>
    <mesh name="left_thumb_MC" file="sharpa_hand/left_thumb_MC.STL"/>
    <mesh name="left_thumb_MCP_VL_visual" file="sharpa_hand/left_thumb_MCP_VL_visual.STL"/>
    <mesh name="left_thumb_PP_visual" file="sharpa_hand/left_thumb_PP_visual.STL"/>
    <mesh name="left_thumb_PP" file="sharpa_hand/left_thumb_PP.STL"/>
    <mesh name="left_thumb_DP_visual" file="sharpa_hand/left_thumb_DP_visual.STL"/>
    <mesh name="left_thumb_DP" file="sharpa_hand/left_thumb_DP.STL"/>
    <mesh name="thumb_elastomer_surface" file="sharpa_hand/thumb_elastomer_surface.STL"/>
    <mesh name="left_MCP_VL_visual" file="sharpa_hand/left_MCP_VL_visual.STL"/>
    <mesh name="left_PP_visual" file="sharpa_hand/left_PP_visual.STL"/>
    <mesh name="left_PP" file="sharpa_hand/left_PP.STL"/>
    <mesh name="left_MP_visual" file="sharpa_hand/left_MP_visual.STL"/>
    <mesh name="left_MP" file="sharpa_hand/left_MP.STL"/>
    <mesh name="left_DP_visual" file="sharpa_hand/left_DP_visual.STL"/>
    <mesh name="left_DP" file="sharpa_hand/left_DP.STL"/>
    <mesh name="elastomer_surface" file="sharpa_hand/elastomer_surface.STL"/>
    <mesh name="left_pinky_MC_visual" file="sharpa_hand/left_pinky_MC_visual.STL"/>
    <mesh name="left_pinky_MC" file="sharpa_hand/left_pinky_MC.STL"/>
  </asset>
  <option cone="elliptic" impratio="10"/>
  <default>
    <default class="CMC_joint">
      <joint armature="0.0032" frictionloss="0.132" damping="4.20E-05"/>
    </default>
    <default class="PCMC_joint">
      <joint armature="0.00012" frictionloss="0.012" damping="4.20E-05"/>
    </default>
    <default class="MCP_joint">
      <joint armature="0.00265" frictionloss="0.07456" damping="2.38E-05"/>
    </default>
    <default class="PIP_joint">
      <joint armature="0.0006" frictionloss="0.01276" damping="4.06E-06"/>
    </default>
    <default class="DIP_joint">
      <joint armature="0.00042" frictionloss="0.00378738" damping="1.21E-06"/>
    </default>
    <default class="elastomer_geom">
      <geom solref="0.06 0.9"/>
    </default>
  </default>
  <worldbody>
    <light name="key" pos="0.5 0.5 1.3" dir="-1 -0.5 -0.5" cutoff="45" diffuse="0.3 0.3 0.3" directional="true"/>
    <light name="fill" pos="0.30000000000000004 -0.7 1.2000000000000002" dir="-0.8 0.5 -0.6" cutoff="60" diffuse="0.18 0.18 0.18" directional="true"/>
    <light name="back" pos="-1.3 0 2.0" dir="-1 0 1" cutoff="50" diffuse="0.5 0.5 0.5" directional="true"/>
    <body name="concrete-slab" pos="0 0 0.6">
      <geom name="concrete-slab-concrete" type="box" group="1" material="concrete-slab-concrete" size="0.7 0.7 0.05" pos="0 0 -0.05"/>
    </body>
    <body name="box-1" pos="-0.15 0 0.7">
      <joint type="free" name="box-1"/>
      <geom name="box-1" type="box" size="0.025 0.025 0.025" rgba="1 0 0 1" mass="1"/>
      <site name="box-1" pos="0 0 0" size="0.005"/>
    </body>
    <body name="box-2" pos="0 0 0.7">
      <joint type="free" name="box-2"/>
      <geom name="box-2" type="box" size="0.025 0.025 0.025" rgba="0 1 0 1" mass="1"/>
      <site name="box-2" pos="0 0 0" size="0.005"/>
    </body>
    <body name="box-3" pos="0.15 0 0.7">
      <joint type="free" name="box-3"/>
      <geom name="box-3" type="box" size="0.025 0.025 0.025" rgba="0 0 1 1" mass="1"/>
      <site name="box-3" pos="0 0 0" size="0.005"/>
    </body>
    <camera name="back" pos="0.0 0.9000000000000001 1.075" fovy="42.5" xyaxes="-1.0 0.0 0.0 0.0 -0.20039623614870655 0.9797149322825656"/>
    <camera name="front" pos="0.0 -1.3 1.075" fovy="42.5" xyaxes="1.0 0.0 0.0 -0.0 0.20039623614870655 0.9797149322825656"/>
    <body name="sharpa_hand_right" pos="-0.5 -0.15 1.1" quat="0 1 0 1">
      <joint name="rh_forearm_free" type="free"/>
      <body name="right_hand_C_MC" pos="0 0 0">
        <inertial pos="0.0060282 0.00091891 0.038914" mass="0.72045" diaginertia="0.00071328 0.00081371 0.00020795"/>
        <geom type="mesh" contype="0" conaffinity="0" group="1" density="0" rgba="0.79216 0.81961 0.93333 1" mesh="right_hand_C_MC_visual" name="right_hand_C_MC_visual"/>
        <geom type="mesh" contype="1" conaffinity="1" group="3" rgba="0.79216 0.81961 0.93333 1" mesh="right_hand_C_MC" name="right_hand_C_MC"/>
        <body name="sharpa_palm_site" pos="0 0 0.02" quat="-0.5 -0.5 0.5 0.5">
          <site name="sharpa_palm_site" group="4" size="0.002 0.002 0.002"/>
        </body>
        <camera name="wrist_right" pos="0.1 0 0" quat="0.183013 -0.683013 0.683013 -0.183013" fovy="77.55214222201174"/>
        <body name="right_thumb_CMC_VL" pos="0.01 0.026 0.0212" quat="-2.59734e-06 0.707105 0.707108 -2.59735e-06">
          <inertial pos="0 0 0" mass="1e-06" diaginertia="2e-12 2e-12 2e-12"/>
          <joint name="right_thumb_CMC_FE" pos="0 0 0" axis="0 0 1" range="-0.1745 1.9199" class="CMC_joint"/>
          <geom type="mesh" contype="0" conaffinity="0" group="1" density="0" rgba="0.79216 0.81961 0.93333 1" mesh="right_thumb_CMC_VL_visual"/>
          <body name="right_thumb_MC" pos="0 -0.005 0" quat="0.65328 -0.653282 0.270598 0.270599">
            <inertial pos="0.0378875 -0.0105001 0.00999649" quat="-0.224946 0.690249 -0.156115 0.669764" mass="0.116" diaginertia="3.87084e-05 3.37238e-05 1.64399e-05"/>
            <joint name="right_thumb_CMC_AA" pos="0 0 0" axis="0 0 1" range="-0.3491 0.3491" class="CMC_joint"/>
            <geom type="mesh" contype="0" conaffinity="0" group="1" density="0" rgba="0.79216 0.81961 0.93333 1" mesh="right_thumb_MC_visual" name="right_thumb_MC_visual"/>
            <geom type="mesh" contype="1" conaffinity="1" group="3" rgba="0.79216 0.81961 0.93333 1" mesh="right_thumb_MC" name="right_thumb_MC"/>
            <body name="right_thumb_MCP_VL" pos="0.065 -0.006 0.010392" quat="0.965926 0.25882 0 0">
              <inertial pos="4.8e-09 0.000869809 -3.6e-09" mass="1e-06" diaginertia="2e-12 2e-12 2e-12"/>
              <joint name="right_thumb_MCP_FE" pos="0 0 0" axis="0 0 1" range="-0.5236 1.3963" class="MCP_joint"/>
              <geom type="mesh" contype="0" conaffinity="0" group="1" density="0" rgba="0.79216 0.81961 0.93333 1" mesh="right_thumb_MCP_VL_visual"/>
              <body name="right_thumb_PP" quat="0.707105 -0.707108 0 0">
                <body name="sharpa_thumb_proximal_site" pos="0 0 0" quat="0.5 0.5 0.5 -0.5">
                  <site name="sharpa_thumb_proximal_site" group="4" size="0.002 0.002 0.002"/>
                </body>
                <inertial pos="0.0219649 -0.000155785 -0.00149071" quat="0.47361 0.526063 0.5236 0.474125" mass="0.04955" diaginertia="4.63211e-06 4.39424e-06 2.59479e-06"/>
                <joint name="right_thumb_MCP_AA" pos="0 0 0" axis="0 0 1" range="-0.3491 0.3491" class="MCP_joint"/>
                <geom type="mesh" contype="0" conaffinity="0" group="1" density="0" rgba="0.79216 0.81961 0.93333 1" mesh="right_thumb_PP_visual" name="right_thumb_PP_visual"/>
                <geom type="mesh" contype="1" conaffinity="1" group="3" rgba="0.79216 0.81961 0.93333 1" mesh="right_thumb_PP" name="right_thumb_PP"/>
                <body name="right_thumb_DP" pos="0.039 0 0" quat="0.707105 0.707108 0 0">
                  <inertial pos="0.009858 -0.0101251 0.00044685" quat="0.650084 0.202839 -0.647252 0.342507" mass="0.005987" diaginertia="8.79951e-07 8.08527e-07 2.50483e-07"/>
                  <joint name="right_thumb_IP" pos="0 0 0" axis="0 0 1" range="0 1.7453" class="PIP_joint"/>
                  <geom type="mesh" contype="0" conaffinity="0" group="1" density="0" rgba="0.79216 0.81961 0.93333 1" mesh="right_thumb_DP_visual" name="right_thumb_DP_visual"/>
                  <geom type="mesh" contype="1" conaffinity="1" group="3" rgba="0.79216 0.81961 0.93333 1" mesh="right_thumb_DP" name="right_thumb_DP"/>
                  <geom quat="0.499998 0.5 -0.5 0.500002" type="mesh" contype="0" conaffinity="0" group="1" density="0" rgba="0.2 1 0.2 1" mesh="thumb_elastomer" name="right_thumb_elastomer_visual"/>
                  <geom quat="0.499998 0.5 -0.5 0.500002" type="mesh" contype="1" conaffinity="1" group="3" rgba="0.2 1 0.2 1" mesh="thumb_elastomer" name="right_thumb_elastomer" class="elastomer_geom"/>
                  <body name="sharpa_thumb_distal_site" pos="0 0 0" quat="0.5 0.5 0.5 -0.5">
                    <site name="sharpa_thumb_distal_site" group="4" size="0.002 0.002 0.002"/>
                  </body>
                  <body name="sharpa_thumb_tip_site" pos="0.027 0 0" quat="0.5 0.5 0.5 -0.5">
                    <site name="sharpa_thumb_tip_site" group="4" size="0.002 0.002 0.002"/>
                  </body>
                </body>
              </body>
            </body>
          </body>
        </body>
        <body name="right_index_MCP_VL" pos="0.001 0.0303 0.0957" quat="0.499998 -0.500002 -0.5 -0.5">
          <inertial pos="4.8e-09 0.00086981 -3.6e-09" mass="1e-06" diaginertia="2e-12 2e-12 2e-12"/>
          <joint name="right_index_MCP_FE" pos="0 0 0" axis="0 0 1" range="-0.17453293 1.5708" class="MCP_joint"/>
          <geom type="mesh" contype="0" conaffinity="0" group="1" density="0" rgba="0.79216 0.81961 0.93333 1" mesh="right_MCP_VL_visual"/>
          <geom type="mesh" contype="1" conaffinity="1" group="3" rgba="0.79216 0.81961 0.93333 1" mesh="MCP_VL"/>
          <body name="right_index_PP" quat="0.707105 -0.707108 0 0">
            <inertial pos="0.0243772 1.00263e-06 -0.000755901" quat="0.479204 0.519977 0.519877 0.479286" mass="0.04138" diaginertia="6.82371e-06 6.54097e-06 2.16753e-06"/>
            <joint name="right_index_MCP_AA" pos="0 0 0" axis="0 0 1" range="-0.3491 0.3491" class="MCP_joint"/>
            <geom type="mesh" contype="0" conaffinity="0" group="1" density="0" rgba="0.79216 0.81961 0.93333 1" mesh="right_PP_visual" name="right_index_PP_visual"/>
            <geom type="mesh" contype="1" conaffinity="1" group="3" rgba="0.79216 0.81961 0.93333 1" mesh="right_PP" name="right_index_PP"/>
            <body name="sharpa_index_proximal_site" pos="0 0 0" quat="0 0.70710678 0.70710678 0">
              <site name="sharpa_index_proximal_site" group="4" size="0.002 0.002 0.002"/>
            </body>
            <body name="right_index_MP" pos="0.047 0 0" quat="0.707105 0.707108 0 0">
              <inertial pos="0.015316 -0.00138561 6.28778e-08" quat="-0.0196261 0.706839 0.0195184 0.706832" mass="0.02509" diaginertia="2.28516e-06 2.26758e-06 9.99868e-07"/>
              <joint name="right_index_PIP" pos="0 0 0" axis="0 0 1" range="0 1.7453" class="PIP_joint"/>
              <geom type="mesh" contype="0" conaffinity="0" group="1" density="0" rgba="0.79216 0.81961 0.93333 1" mesh="right_MP_visual" name="right_index_MP_visual"/>
              <geom type="mesh" contype="1" conaffinity="1" group="3" rgba="0.79216 0.81961 0.93333 1" mesh="right_MP" name="right_index_MP"/>
              <body name="sharpa_index_intermediate_site" pos="0 0 0" quat="0.5 0.5 0.5 -0.5">
                <site name="sharpa_index_intermediate_site" group="4" size="0.002 0.002 0.002"/>
              </body>
              <body name="right_index_DP" pos="0.0315 0 0">
                <inertial pos="0.00931268 -0.00769378 0.000111581" quat="0.64397 0.245697 -0.649334 0.321406" mass="0.004103" diaginertia="4.23752e-07 3.85411e-07 1.37217e-07"/>
                <joint name="right_index_DIP" pos="0 0 0" axis="0 0 1" range="0 1.3963" class="DIP_joint"/>
                <geom type="mesh" contype="0" conaffinity="0" group="1" density="0" rgba="0.79216 0.81961 0.93333 1" mesh="right_DP_visual" name="right_index_DP_visual"/>
                <geom type="mesh" contype="1" conaffinity="1" group="3" rgba="0.79216 0.81961 0.93333 1" mesh="right_DP" name="right_index_DP"/>
                <geom quat="0.499998 0.5 -0.5 0.500002" type="mesh" contype="0" conaffinity="0" group="1" density="0" rgba="0.2 1 0.2 1" mesh="elastomer" name="right_index_elastomer_visual"/>
                <geom quat="0.499998 0.5 -0.5 0.500002" type="mesh" contype="1" conaffinity="1" group="3" rgba="0.2 1 0.2 1" mesh="elastomer" name="right_index_elastomer" class="elastomer_geom"/>
                <body name="sharpa_index_distal_site" pos="0 0 0" quat="0.5 0.5 0.5 -0.5">
                  <site name="sharpa_index_distal_site" group="4" size="0.002 0.002 0.002"/>
                </body>
                <body name="sharpa_index_tip_site" pos="0.027 0 0" quat="0.5 0.5 0.5 -0.5">
                  <site name="sharpa_index_tip_site" group="4" size="0.002 0.002 0.002"/>
                </body>
              </body>
            </body>
          </body>
        </body>
        <body name="right_middle_MCP_VL" pos="0 0.01 0.0987" quat="0.499998 -0.500002 -0.5 -0.5">
          <inertial pos="0 0 0" mass="1e-06" diaginertia="2e-12 2e-12 2e-12"/>
          <joint name="right_middle_MCP_FE" pos="0 0 0" axis="0 0 1" range="-0.17453293 1.5708" class="MCP_joint"/>
          <geom type="mesh" contype="0" conaffinity="0" group="1" density="0" rgba="0.79216 0.81961 0.93333 1" mesh="right_MCP_VL_visual"/>
          <geom type="mesh" contype="1" conaffinity="1" group="3" rgba="0.79216 0.81961 0.93333 1" mesh="MCP_VL"/>
          <body name="right_middle_PP" quat="0.707105 -0.707108 0 0">
            <inertial pos="0.0243772 1.00263e-06 -0.000755901" quat="0.479204 0.519977 0.519877 0.479286" mass="0.04138" diaginertia="6.82371e-06 6.54097e-06 2.16753e-06"/>
            <joint name="right_middle_MCP_AA" pos="0 0 0" axis="0 0 1" range="-0.3491 0.3491" class="MCP_joint"/>
            <geom type="mesh" contype="0" conaffinity="0" group="1" density="0" rgba="0.79216 0.81961 0.93333 1" mesh="right_PP_visual" name="right_middle_PP_visual"/>
            <geom type="mesh" contype="1" conaffinity="1" group="3" rgba="0.79216 0.81961 0.93333 1" mesh="right_PP" name="right_middle_PP"/>
            <body name="sharpa_middle_proximal_site" pos="0 0 0" quat="0 0.70710678 0.70710678 0">
              <site name="sharpa_middle_proximal_site" group="4" size="0.002 0.002 0.002"/>
            </body>
            <body name="right_middle_MP" pos="0.047 0 0" quat="0.707105 0.707108 0 0">
              <inertial pos="0.015316 -0.00138561 6.28778e-08" quat="-0.0196261 0.706839 0.0195184 0.706832" mass="0.02509" diaginertia="2.28516e-06 2.26758e-06 9.99868e-07"/>
              <joint name="right_middle_PIP" pos="0 0 0" axis="0 0 1" range="0 1.7453" class="PIP_joint"/>
              <geom type="mesh" contype="0" conaffinity="0" group="1" density="0" rgba="0.79216 0.81961 0.93333 1" mesh="right_MP_visual" name="right_middle_MP_visual"/>
              <geom type="mesh" contype="1" conaffinity="1" group="3" rgba="0.79216 0.81961 0.93333 1" mesh="right_MP" name="right_middle_MP"/>
              <body name="sharpa_middle_intermediate_site" pos="0 0 0" quat="0.5 0.5 0.5 -0.5">
                <site name="sharpa_middle_intermediate_site" group="4" size="0.002 0.002 0.002"/>
              </body>
              <body name="right_middle_DP" pos="0.0315 0 0">
                <inertial pos="0.00931268 -0.00769378 0.000111581" quat="0.64397 0.245697 -0.649334 0.321406" mass="0.004103" diaginertia="4.23752e-07 3.85411e-07 1.37217e-07"/>
                <joint name="right_middle_DIP" pos="0 0 0" axis="0 0 1" range="0 1.3963" class="DIP_joint"/>
                <geom type="mesh" contype="0" conaffinity="0" group="1" density="0" rgba="0.79216 0.81961 0.93333 1" mesh="right_DP_visual" name="right_middle_DP_visual"/>
                <geom type="mesh" contype="1" conaffinity="1" group="3" rgba="0.79216 0.81961 0.93333 1" mesh="right_DP" name="right_middle_DP"/>
                <geom quat="0.5 0.5 -0.5 0.5" type="mesh" contype="0" conaffinity="0" group="1" density="0" rgba="0.2 1 0.2 1" mesh="elastomer" name="right_middle_elastomer_visual"/>
                <geom quat="0.5 0.5 -0.5 0.5" type="mesh" contype="1" conaffinity="1" group="3" rgba="0.2 1 0.2 1" mesh="elastomer" name="right_middle_elastomer" class="elastomer_geom"/>
                <body name="sharpa_middle_distal_site" pos="0 0 0" quat="0.5 0.5 0.5 -0.5">
                  <site name="sharpa_middle_distal_site" group="4" size="0.002 0.002 0.002"/>
                </body>
                <body name="sharpa_middle_tip_site" pos="0.027 0 0" quat="0.5 0.5 0.5 -0.5">
                  <site name="sharpa_middle_tip_site" group="4" size="0.002 0.002 0.002"/>
                </body>
              </body>
            </body>
          </body>
        </body>
        <body name="right_ring_MCP_VL" pos="0.0015 -0.0103 0.0927" quat="0.499998 -0.500002 -0.5 -0.5">
          <inertial pos="4.8e-09 0.00086981 -3.6e-09" mass="1e-06" diaginertia="2e-12 2e-12 2e-12"/>
          <joint name="right_ring_MCP_FE" pos="0 0 0" axis="0 0 1" range="-0.17453293 1.5708" class="MCP_joint"/>
          <geom type="mesh" contype="0" conaffinity="0" group="1" density="0" rgba="0.79216 0.81961 0.93333 1" mesh="right_MCP_VL_visual"/>
          <geom type="mesh" contype="1" conaffinity="1" group="3" rgba="0.79216 0.81961 0.93333 1" mesh="MCP_VL"/>
          <body name="right_ring_PP" quat="0.707105 -0.707108 0 0">
            <inertial pos="0.0243772 1.00263e-06 -0.000755901" quat="0.479204 0.519977 0.519877 0.479286" mass="0.04138" diaginertia="6.82371e-06 6.54097e-06 2.16753e-06"/>
            <joint name="right_ring_MCP_AA" pos="0 0 0" axis="0 0 1" range="-0.3491 0.3491" class="MCP_joint"/>
            <geom type="mesh" contype="0" conaffinity="0" group="1" density="0" rgba="0.79216 0.81961 0.93333 1" mesh="right_PP_visual" name="right_ring_PP_visual"/>
            <geom type="mesh" contype="1" conaffinity="1" group="3" rgba="0.79216 0.81961 0.93333 1" mesh="right_PP" name="right_ring_PP"/>
            <body name="sharpa_ring_proximal_site" pos="0 0 0" quat="0 0.70710678 0.70710678 0">
              <site name="sharpa_ring_proximal_site" group="4" size="0.002 0.002 0.002"/>
            </body>
            <body name="right_ring_MP" pos="0.047 0 0" quat="0.707105 0.707108 0 0">
              <inertial pos="0.015316 -0.00138561 6.28778e-08" quat="-0.0196261 0.706839 0.0195184 0.706832" mass="0.02509" diaginertia="2.28516e-06 2.26758e-06 9.99868e-07"/>
              <joint name="right_ring_PIP" pos="0 0 0" axis="0 0 1" range="0 1.7453" class="PIP_joint"/>
              <geom type="mesh" contype="0" conaffinity="0" group="1" density="0" rgba="0.79216 0.81961 0.93333 1" mesh="right_MP_visual" name="right_ring_MP_visual"/>
              <geom type="mesh" contype="1" conaffinity="1" group="3" rgba="0.79216 0.81961 0.93333 1" mesh="right_MP" name="right_ring_MP"/>
              <body name="sharpa_ring_intermediate_site" pos="0 0 0" quat="0.5 0.5 0.5 -0.5">
                <site name="sharpa_ring_intermediate_site" group="4" size="0.002 0.002 0.002"/>
              </body>
              <body name="right_ring_DP" pos="0.0315 0 0">
                <inertial pos="0.00931268 -0.00769378 0.000111581" quat="0.64397 0.245697 -0.649334 0.321406" mass="0.004103" diaginertia="4.23752e-07 3.85411e-07 1.37217e-07"/>
                <joint name="right_ring_DIP" pos="0 0 0" axis="0 0 1" range="0 1.3963" class="DIP_joint"/>
                <geom type="mesh" contype="0" conaffinity="0" group="1" density="0" rgba="0.79216 0.81961 0.93333 1" mesh="right_DP_visual" name="right_ring_DP_visual"/>
                <geom type="mesh" contype="1" conaffinity="1" group="3" rgba="0.79216 0.81961 0.93333 1" mesh="right_DP" name="right_ring_DP"/>
                <geom quat="0.499998 0.5 -0.5 0.500002" type="mesh" contype="0" conaffinity="0" group="1" density="0" rgba="0.2 1 0.2 1" mesh="elastomer" name="right_ring_elastomer_visual"/>
                <geom quat="0.499998 0.5 -0.5 0.500002" type="mesh" contype="1" conaffinity="1" group="3" rgba="0.2 1 0.2 1" mesh="elastomer" name="right_ring_elastomer" class="elastomer_geom"/>
                <body name="sharpa_ring_distal_site" pos="0 0 0" quat="0.5 0.5 0.5 -0.5">
                  <site name="sharpa_ring_distal_site" group="4" size="0.002 0.002 0.002"/>
                </body>
                <body name="sharpa_ring_tip_site" pos="0.027 0 0" quat="0.5 0.5 0.5 -0.5">
                  <site name="sharpa_ring_tip_site" group="4" size="0.002 0.002 0.002"/>
                </body>
              </body>
            </body>
          </body>
        </body>
        <body name="right_pinky_MC" pos="0.01136 -0.0263 0.0867" quat="-3.67321e-06 0 0 1">
          <inertial pos="0.0107985 0.00598801 -0.0335125" quat="0.709657 -0.106152 -0.0812795 0.691746" mass="0.12541" diaginertia="3.57685e-05 2.46485e-05 2.14424e-05"/>
          <joint name="right_pinky_CMC" pos="0 0 0" axis="0 0 1" range="0 0.2618" class="PCMC_joint"/>
          <geom type="mesh" contype="0" conaffinity="0" group="1" density="0" rgba="0.79216 0.81961 0.93333 1" mesh="right_pinky_MC_visual" name="right_pinky_MC_visual"/>
          <geom type="mesh" contype="1" conaffinity="1" group="3" rgba="0.79216 0.81961 0.93333 1" mesh="right_pinky_MC" name="right_pinky_MC"/>
          <body name="right_pinky_MCP_VL" pos="0.00836 0.0048 0" quat="0.499998 0.5 -0.5 0.500002">
            <inertial pos="4.8e-09 0.00086981 -3.6e-09" mass="1e-06" diaginertia="2e-12 2e-12 2e-12"/>
            <joint name="right_pinky_MCP_FE" pos="0 0 0" axis="0 0 1" range="-0.17453293 1.5708" class="MCP_joint"/>
            <geom type="mesh" contype="0" conaffinity="0" group="1" density="0" rgba="0.79216 0.81961 0.93333 1" mesh="right_MCP_VL_visual"/>
            <geom type="mesh" contype="1" conaffinity="1" group="3" rgba="0.79216 0.81961 0.93333 1" mesh="MCP_VL"/>
            <body name="right_pinky_PP" quat="0.707105 -0.707108 0 0">
              <inertial pos="0.0243772 1.00263e-06 -0.000755901" quat="0.479204 0.519977 0.519877 0.479286" mass="0.04138" diaginertia="6.82371e-06 6.54097e-06 2.16753e-06"/>
              <joint name="right_pinky_MCP_AA" pos="0 0 0" axis="0 0 1" range="-0.3491 0.3491" class="MCP_joint"/>
              <geom type="mesh" contype="0" conaffinity="0" group="1" density="0" rgba="0.79216 0.81961 0.93333 1" mesh="right_PP_visual" name="right_pinky_PP_visual"/>
              <geom type="mesh" contype="1" conaffinity="1" group="3" rgba="0.79216 0.81961 0.93333 1" mesh="right_PP" name="right_pinky_PP"/>
              <body name="sharpa_pinky_proximal_site" pos="0 0 0" quat="0 0.70710678 0.70710678 0">
                <site name="sharpa_pinky_proximal_site" group="4" size="0.002 0.002 0.002"/>
              </body>
              <body name="right_pinky_MP" pos="0.047 0 0" quat="0.707105 0.707108 0 0">
                <inertial pos="0.015316 -0.00138561 6.28778e-08" quat="-0.0196261 0.706839 0.0195184 0.706832" mass="0.02509" diaginertia="2.28516e-06 2.26758e-06 9.99868e-07"/>
                <joint name="right_pinky_PIP" pos="0 0 0" axis="0 0 1" range="0 1.7453" class="PIP_joint"/>
                <geom type="mesh" contype="0" conaffinity="0" group="1" density="0" rgba="0.79216 0.81961 0.93333 1" mesh="right_MP_visual" name="right_pinky_MP_visual"/>
                <geom type="mesh" contype="1" conaffinity="1" group="3" rgba="0.79216 0.81961 0.93333 1" mesh="right_MP" name="right_pinky_MP"/>
                <body name="sharpa_pinky_intermediate_site" pos="0 0 0" quat="0.5 0.5 0.5 -0.5">
                  <site name="sharpa_pinky_intermediate_site" group="4" size="0.002 0.002 0.002"/>
                </body>
                <body name="right_pinky_DP" pos="0.0315 0 0">
                  <inertial pos="0.00931268 -0.00769376 0.000111581" quat="0.64397 0.245701 -0.649333 0.321403" mass="0.004103" diaginertia="4.23753e-07 3.85412e-07 1.37217e-07"/>
                  <joint name="right_pinky_DIP" pos="0 0 0" axis="0 0 1" range="0 1.3963" class="DIP_joint"/>
                  <geom type="mesh" contype="0" conaffinity="0" group="1" density="0" rgba="0.79216 0.81961 0.93333 1" mesh="right_DP_visual" name="right_pinky_DP_visual"/>
                  <geom type="mesh" contype="1" conaffinity="1" group="3" rgba="0.79216 0.81961 0.93333 1" mesh="right_DP" name="right_pinky_DP"/>
                  <geom quat="0.499998 0.5 -0.5 0.500002" type="mesh" contype="0" conaffinity="0" group="1" density="0" rgba="0.1 1 0.2 1" mesh="elastomer" name="right_pinky_elastomer_visual"/>
                  <geom quat="0.499998 0.5 -0.5 0.500002" type="mesh" contype="1" conaffinity="1" group="3" rgba="0.1 1 0.2 1" mesh="elastomer" name="right_pinky_elastomer" class="elastomer_geom"/>
                  <body name="sharpa_pinky_distal_site" pos="0 0 0" quat="0.5 0.5 0.5 -0.5">
                    <site name="sharpa_pinky_distal_site" group="4" size="0.002 0.002 0.002"/>
                  </body>
                  <body name="sharpa_pinky_tip_site" pos="0.027 0 0" quat="0.5 0.5 0.5 -0.5">
                    <site name="sharpa_pinky_tip_site" group="4" size="0.002 0.002 0.002"/>
                  </body>
                </body>
              </body>
            </body>
          </body>
        </body>
      </body>
    </body>
    <body name="sharpa_hand_left" pos="-0.5 0.15 1.1" quat="0 1 0 1">
      <joint name="lh_forearm_free" type="free"/>
      <body name="left_hand_C_MC" pos="0 0 0">
        <inertial pos="0.0060282 0.00091891 0.038914" mass="0.72045" diaginertia="0.00071328 0.00081371 0.00020795"/>
        <geom type="mesh" contype="0" conaffinity="0" group="1" density="0" rgba="0.79216 0.81961 0.93333 1" mesh="left_hand_C_MC_visual" name="left_hand_C_MC_visual"/>
        <geom type="mesh" contype="1" conaffinity="1" group="3" rgba="0.79216 0.81961 0.93333 1" mesh="left_hand_C_MC" name="left_hand_C_MC"/>
        <body name="left_sharpa_palm_site" pos="0 0 0.02" quat="-0.5 -0.5 0.5 0.5">
          <site name="left_sharpa_palm_site" group="4" size="0.002 0.002 0.002"/>
        </body>
        <camera name="wrist_left" pos="0.1 0 0" quat="0.183013 -0.683013 0.683013 -0.183013" fovy="77.55214222201174"/>
        <body name="left_thumb_CMC_VL" pos="0.01 -0.026 0.0212" quat="0.707105 0 0 -0.707108">
          <inertial pos="0 0 0" mass="1e-06" diaginertia="2e-12 2e-12 2e-12"/>
          <joint name="left_thumb_CMC_FE" pos="0 0 0" axis="0 0 1" range="-0.1745 1.9199" class="CMC_joint"/>
          <geom type="mesh" contype="0" conaffinity="0" group="1" density="0" rgba="0.79216 0.81961 0.93333 1" mesh="left_thumb_CMC_VL_visual"/>
          <body name="left_thumb_MC" pos="0 -0.005 0" quat="0.65328 0.653282 -0.270598 0.270599">
            <inertial pos="0.0385056 -0.0105846 -0.00991873" quat="0.158428 0.667584 0.222963 0.692474" mass="0.116" diaginertia="3.83518e-05 3.34032e-05 1.641e-05"/>
            <joint name="left_thumb_CMC_AA" pos="0 0 0" axis="0 0 1" range="-0.3491 0.3491" class="CMC_joint"/>
            <geom type="mesh" contype="0" conaffinity="0" group="1" density="0" rgba="0.79216 0.81961 0.93333 1" mesh="left_thumb_MC_visual" name="left_thumb_MC_visual"/>
            <geom type="mesh" contype="1" conaffinity="1" group="3" rgba="0.79216 0.81961 0.93333 1" mesh="left_thumb_MC" name="left_thumb_MC"/>
            <body name="left_thumb_MCP_VL" pos="0.065 -0.006 -0.010392" quat="0.965926 -0.25882 0 0">
              <inertial pos="4.8e-09 0.000869809 -3.6e-09" mass="0.001" diaginertia="2e-12 2e-12 2e-12"/>
              <joint name="left_thumb_MCP_FE" pos="0 0 0" axis="0 0 1" range="-0.5236 1.3963" class="MCP_joint"/>
              <geom type="mesh" contype="0" conaffinity="0" group="1" density="0" rgba="0.79216 0.81961 0.93333 1" mesh="left_thumb_MCP_VL_visual"/>
              <body name="left_thumb_PP" quat="0.707105 0.707108 0 0">
                <body name="left_sharpa_thumb_proximal_site" pos="0 0 0" quat="0.5 0.5 0.5 -0.5">
                  <site name="left_sharpa_thumb_proximal_site" group="4" size="0.002 0.002 0.002"/>
                </body>
                <inertial pos="0.0219483 -0.00015581 0.00149446" quat="0.526585 0.473016 0.473458 0.524215" mass="0.04955" diaginertia="4.60001e-06 4.35675e-06 2.57733e-06"/>
                <joint name="left_thumb_MCP_AA" pos="0 0 0" axis="0 0 1" range="-0.3491 0.3491" class="MCP_joint"/>
                <geom type="mesh" contype="0" conaffinity="0" group="1" density="0" rgba="0.79216 0.81961 0.93333 1" mesh="left_thumb_PP_visual" name="left_thumb_PP_visual"/>
                <geom type="mesh" contype="1" conaffinity="1" group="3" rgba="0.79216 0.81961 0.93333 1" mesh="left_thumb_PP" name="left_thumb_PP"/>
                <body name="left_thumb_DP" pos="0.039 0 0" quat="0.707105 -0.707108 0 0">
                  <inertial pos="0.00985829 -0.0101254 0.00044771" quat="0.649916 0.20258 -0.647399 0.342703" mass="0.006986" diaginertia="8.79989e-07 8.08573e-07 2.50588e-07"/>
                  <joint name="left_thumb_IP" pos="0 0 0" axis="0 0 1" range="0 1.7453" class="PIP_joint"/>
                  <geom type="mesh" contype="0" conaffinity="0" group="1" density="0" rgba="0.79216 0.81961 0.93333 1" mesh="left_thumb_DP_visual" name="left_thumb_DP_visual"/>
                  <geom type="mesh" contype="1" conaffinity="1" group="3" rgba="0.79216 0.81961 0.93333 1" mesh="left_thumb_DP" name="left_thumb_DP"/>
                  <geom quat="0.5 0.5 -0.5 0.5" type="mesh" contype="0" conaffinity="0" group="1" density="0" rgba="0.2 1 0.2 1" mesh="thumb_elastomer"/>
                  <geom contype="1" conaffinity="1" group="3" quat="0.5 0.5 -0.5 0.5" type="mesh" rgba="0.2 1 0.2 1" mesh="thumb_elastomer" name="left_thumb_elastomer" class="elastomer_geom"/>
                  <body name="left_sharpa_thumb_distal_site" pos="0 0 0" quat="0.5 0.5 0.5 -0.5">
                    <site name="left_sharpa_thumb_distal_site" group="4" size="0.002 0.002 0.002"/>
                  </body>
                  <body name="left_sharpa_thumb_tip_site" pos="0.027 0 0" quat="0.5 0.5 0.5 -0.5">
                    <site name="left_sharpa_thumb_tip_site" group="4" size="0.002 0.002 0.002"/>
                  </body>
                </body>
              </body>
            </body>
          </body>
        </body>
        <body name="left_index_MCP_VL" pos="0.001 -0.0303 0.0957" quat="0.499998 -0.500002 -0.5 -0.5">
          <inertial pos="4.8e-09 0.00086981 -3.6e-09" mass="0.001" diaginertia="2e-12 2e-12 2e-12"/>
          <joint name="left_index_MCP_FE" pos="0 0 0" axis="0 0 1" range="-0.17453293 1.5708" class="MCP_joint"/>
          <geom type="mesh" contype="0" conaffinity="0" group="1" density="0" rgba="0.79216 0.81961 0.93333 1" mesh="left_MCP_VL_visual" name="left_index_MCP_VL_visual"/>
          <geom type="mesh" contype="1" conaffinity="1" group="3" rgba="0.79216 0.81961 0.93333 1" mesh="MCP_VL" name="left_index_MCP_VL"/>
          <body name="left_index_PP" quat="0.707105 0.707108 0 0">
            <inertial pos="0.0243772 -1.00263e-06 0.000755901" quat="0.519877 0.479286 0.479204 0.519977" mass="0.04138" diaginertia="6.82371e-06 6.54097e-06 2.16753e-06"/>
            <joint name="left_index_MCP_AA" pos="0 0 0" axis="0 0 1" range="-0.3491 0.3491" class="MCP_joint"/>
            <geom type="mesh" contype="0" conaffinity="0" group="1" density="0" rgba="0.79216 0.81961 0.93333 1" mesh="left_PP_visual" name="left_index_PP_visual"/>
            <geom type="mesh" contype="1" conaffinity="1" group="3" rgba="0.79216 0.81961 0.93333 1" mesh="left_PP" name="left_index_PP"/>
            <body name="left_sharpa_index_proximal_site" pos="0 0 0" quat="0 0.70710678 0.70710678 0">
              <site name="left_sharpa_index_proximal_site" group="4" size="0.002 0.002 0.002"/>
            </body>
            <body name="left_index_MP" pos="0.047 0 0" quat="0.707105 -0.707108 0 0">
              <inertial pos="0.015316 -0.00138561 6.27987e-08" quat="-0.0196259 0.706839 0.0195186 0.706832" mass="0.02509" diaginertia="2.28516e-06 2.26758e-06 9.99868e-07"/>
              <joint name="left_index_PIP" pos="0 0 0" axis="0 0 1" range="0 1.7453" class="PIP_joint"/>
              <geom type="mesh" contype="0" conaffinity="0" group="1" density="0" rgba="0.79216 0.81961 0.93333 1" mesh="left_MP_visual" name="left_index_MP_visual"/>
              <geom type="mesh" contype="1" conaffinity="1" group="3" rgba="0.79216 0.81961 0.93333 1" mesh="left_MP" name="left_index_MP"/>
              <body name="left_sharpa_index_intermediate_site" pos="0 0 0" quat="0.5 0.5 0.5 -0.5">
                <site name="left_sharpa_index_intermediate_site" group="4" size="0.002 0.002 0.002"/>
              </body>
              <body name="left_index_DP" pos="0.0315 0 0">
                <inertial pos="0.00931302 -0.00769378 0.000111984" quat="0.643869 0.245527 -0.649442 0.321517" mass="0.005102" diaginertia="4.23794e-07 3.8546e-07 1.37255e-07"/>
                <joint name="left_index_DIP" pos="0 0 0" axis="0 0 1" range="0 1.3963" class="DIP_joint"/>
                <geom type="mesh" contype="0" conaffinity="0" group="1" density="0" rgba="0.79216 0.81961 0.93333 1" mesh="left_DP_visual" name="left_index_DP_visual"/>
                <geom type="mesh" contype="1" conaffinity="1" group="3" rgba="0.79216 0.81961 0.93333 1" mesh="left_DP" name="left_index_DP"/>
                <geom quat="0.5 0.5 -0.5 0.5" type="mesh" contype="0" conaffinity="0" group="1" density="0" rgba="0.2 1 0.2 1" solref="0.06 0.9" mesh="elastomer" name="left_index_elastomer_visual"/>
                <geom contype="1" conaffinity="1" group="3" quat="0.5 0.5 -0.5 0.5" type="mesh" rgba="0.2 1 0.2 1" mesh="elastomer" name="left_index_elastomer"/>
                <body name="left_sharpa_index_distal_site" pos="0 0 0" quat="0.5 0.5 0.5 -0.5">
                  <site name="left_sharpa_index_distal_site" group="4" size="0.002 0.002 0.002"/>
                </body>
                <body name="left_sharpa_index_tip_site" pos="0.027 0 0" quat="0.5 0.5 0.5 -0.5">
                  <site name="left_sharpa_index_tip_site" group="4" size="0.002 0.002 0.002"/>
                </body>
              </body>
            </body>
          </body>
        </body>
        <body name="left_middle_MCP_VL" pos="0 -0.01 0.0987" quat="0.499998 -0.500002 -0.5 -0.5">
          <inertial pos="4.8e-09 0.00086981 -3.6e-09" mass="1e-06" diaginertia="2e-12 2e-12 2e-12"/>
          <joint name="left_middle_MCP_FE" pos="0 0 0" axis="0 0 1" range="-0.17453293 1.5708" class="MCP_joint"/>
          <geom type="mesh" contype="0" conaffinity="0" group="1" density="0" rgba="0.79216 0.81961 0.93333 1" mesh="left_MCP_VL_visual" name="left_middle_MCP_VL_visual"/>
          <geom type="mesh" contype="1" conaffinity="1" group="3" rgba="0.79216 0.81961 0.93333 1" mesh="MCP_VL" name="left_middle_MCP_VL"/>
          <body name="left_middle_PP" quat="0.707105 0.707108 0 0">
            <inertial pos="0.0243772 -1.00263e-06 0.000755901" quat="0.519877 0.479286 0.479204 0.519977" mass="0.04138" diaginertia="6.82371e-06 6.54097e-06 2.16753e-06"/>
            <joint name="left_middle_MCP_AA" pos="0 0 0" axis="0 0 1" range="-0.3491 0.3491" class="MCP_joint"/>
            <geom type="mesh" contype="0" conaffinity="0" group="1" density="0" rgba="0.79216 0.81961 0.93333 1" mesh="left_PP_visual" name="left_middle_PP_visual"/>
            <geom type="mesh" contype="1" conaffinity="1" group="3" rgba="0.79216 0.81961 0.93333 1" mesh="left_PP" name="left_middle_PP"/>
            <body name="left_sharpa_middle_proximal_site" pos="0 0 0" quat="0 0.70710678 0.70710678 0">
              <site name="left_sharpa_middle_proximal_site" group="4" size="0.002 0.002 0.002"/>
            </body>
            <body name="left_middle_MP" pos="0.047 0 0" quat="0.707105 -0.707108 0 0">
              <inertial pos="0.015316 -0.00138561 6.27987e-08" quat="-0.0196259 0.706839 0.0195186 0.706832" mass="0.02509" diaginertia="2.28516e-06 2.26758e-06 9.99868e-07"/>
              <joint name="left_middle_PIP" pos="0 0 0" axis="0 0 1" range="0 1.7453" class="PIP_joint"/>
              <geom type="mesh" contype="0" conaffinity="0" group="1" density="0" rgba="0.79216 0.81961 0.93333 1" mesh="left_MP_visual" name="left_middle_MP_visual"/>
              <geom type="mesh" contype="1" conaffinity="1" group="3" rgba="0.79216 0.81961 0.93333 1" mesh="left_MP" name="left_middle_MP"/>
              <body name="left_sharpa_middle_intermediate_site" pos="0 0 0" quat="0.5 0.5 0.5 -0.5">
                <site name="left_sharpa_middle_intermediate_site" group="4" size="0.002 0.002 0.002"/>
              </body>
              <body name="left_middle_DP" pos="0.0315 0 0">
                <inertial pos="0.00931302 -0.00769378 0.000111984" quat="0.643869 0.245527 -0.649442 0.321517" mass="0.005102" diaginertia="4.23794e-07 3.8546e-07 1.37255e-07"/>
                <joint name="left_middle_DIP" pos="0 0 0" axis="0 0 1" range="0 1.3963" class="DIP_joint"/>
                <geom type="mesh" contype="0" conaffinity="0" group="1" density="0" rgba="0.79216 0.81961 0.93333 1" mesh="left_DP_visual" name="left_middle_DP_visual"/>
                <geom type="mesh" contype="1" conaffinity="1" group="3" rgba="0.79216 0.81961 0.93333 1" mesh="left_DP" name="left_middle_DP"/>
                <geom quat="0.5 0.5 -0.5 0.5" type="mesh" contype="0" conaffinity="0" group="1" density="0" rgba="0.2 1 0.2 1" solref="0.06 0.9" mesh="elastomer" name="left_middle_elastomer_visual"/>
                <geom contype="1" conaffinity="1" group="3" quat="0.5 0.5 -0.5 0.5" type="mesh" rgba="0.2 1 0.2 1" mesh="elastomer" name="left_middle_elastomer"/>
                <body name="left_sharpa_middle_distal_site" pos="0 0 0" quat="0.5 0.5 0.5 -0.5">
                  <site name="left_sharpa_middle_distal_site" group="4" size="0.002 0.002 0.002"/>
                </body>
                <body name="left_sharpa_middle_tip_site" pos="0.027 0 0" quat="0.5 0.5 0.5 -0.5">
                  <site name="left_sharpa_middle_tip_site" group="4" size="0.002 0.002 0.002"/>
                </body>
              </body>
            </body>
          </body>
        </body>
        <body name="left_ring_MCP_VL" pos="0.0015 0.0103 0.0927" quat="0.499998 -0.500002 -0.5 -0.5">
          <inertial pos="4.8e-09 0.00086981 3.6e-09" mass="1e-06" diaginertia="2e-12 2e-12 2e-12"/>
          <joint name="left_ring_MCP_FE" pos="0 0 0" axis="0 0 1" range="-0.17453293 1.5708" class="MCP_joint"/>
          <geom type="mesh" contype="0" conaffinity="0" group="1" density="0" rgba="0.79216 0.81961 0.93333 1" mesh="left_MCP_VL_visual" name="left_ring_MCP_VL_visual"/>
          <geom type="mesh" contype="1" conaffinity="1" group="3" rgba="0.79216 0.81961 0.93333 1" mesh="MCP_VL" name="left_ring_MCP_VL"/>
          <body name="left_ring_PP" quat="0.707105 0.707108 0 0">
            <inertial pos="0.0243772 -1.00263e-06 0.000755901" quat="0.519877 0.479286 0.479204 0.519977" mass="0.04138" diaginertia="6.82371e-06 6.54097e-06 2.16753e-06"/>
            <joint name="left_ring_MCP_AA" pos="0 0 0" axis="0 0 1" range="-0.3491 0.3491" class="MCP_joint"/>
            <geom type="mesh" contype="0" conaffinity="0" group="1" density="0" rgba="0.79216 0.81961 0.93333 1" mesh="left_PP_visual" name="left_ring_PP_visual"/>
            <geom type="mesh" contype="1" conaffinity="1" group="3" rgba="0.79216 0.81961 0.93333 1" mesh="left_PP" name="left_ring_PP"/>
            <body name="left_sharpa_ring_proximal_site" pos="0 0 0" quat="0 0.70710678 0.70710678 0">
              <site name="left_sharpa_ring_proximal_site" group="4" size="0.002 0.002 0.002"/>
            </body>
            <body name="left_ring_MP" pos="0.047 0 0" quat="0.707105 -0.707108 0 0">
              <inertial pos="0.015316 -0.00138561 6.27987e-08" quat="-0.0196259 0.706839 0.0195186 0.706832" mass="0.02509" diaginertia="2.28516e-06 2.26758e-06 9.99868e-07"/>
              <joint name="left_ring_PIP" pos="0 0 0" axis="0 0 1" range="0 1.7453" class="PIP_joint"/>
              <geom type="mesh" contype="0" conaffinity="0" group="1" density="0" rgba="0.79216 0.81961 0.93333 1" mesh="left_MP_visual" name="left_ring_MP_visual"/>
              <geom type="mesh" contype="1" conaffinity="1" group="3" rgba="0.79216 0.81961 0.93333 1" mesh="left_MP" name="left_ring_MP"/>
              <body name="left_sharpa_ring_intermediate_site" pos="0 0 0" quat="0.5 0.5 0.5 -0.5">
                <site name="left_sharpa_ring_intermediate_site" group="4" size="0.002 0.002 0.002"/>
              </body>
              <body name="left_ring_DP" pos="0.0315 0 0">
                <inertial pos="0.00931208 -0.00769378 0.000111984" quat="0.643953 0.245771 -0.649317 0.321417" mass="0.005102" diaginertia="4.23686e-07 3.85387e-07 1.37226e-07"/>
                <joint name="left_ring_DIP" pos="0 0 0" axis="0 0 1" range="0 1.3963" class="DIP_joint"/>
                <geom type="mesh" contype="0" conaffinity="0" group="1" density="0" rgba="0.79216 0.81961 0.93333 1" mesh="left_DP_visual" name="left_ring_DP_visual"/>
                <geom type="mesh" contype="1" conaffinity="1" group="3" rgba="0.79216 0.81961 0.93333 1" mesh="left_DP" name="left_ring_DP"/>
                <geom quat="0.499998 0.5 -0.5 0.500002" type="mesh" contype="0" conaffinity="0" group="1" density="0" rgba="0.2 1 0.2 1" solref="0.06 0.9" mesh="elastomer" name="left_ring_elastomer_visual"/>
                <geom contype="1" conaffinity="1" group="3" quat="0.499998 0.5 -0.5 0.500002" type="mesh" rgba="0.2 1 0.2 1" mesh="elastomer" name="left_ring_elastomer"/>
                <body name="left_sharpa_ring_distal_site" pos="0 0 0" quat="0.5 0.5 0.5 -0.5">
                  <site name="left_sharpa_ring_distal_site" group="4" size="0.002 0.002 0.002"/>
                </body>
                <body name="left_sharpa_ring_tip_site" pos="0.027 0 0" quat="0.5 0.5 0.5 -0.5">
                  <site name="left_sharpa_ring_tip_site" group="4" size="0.002 0.002 0.002"/>
                </body>
              </body>
            </body>
          </body>
        </body>
        <body name="left_pinky_MC" pos="0.01136 0.0263 0.0867" quat="1.34924e-11 3.67321e-06 -1 -3.67321e-06">
          <inertial pos="0.0107985 0.00598801 0.0335125" quat="0.709657 0.106152 0.0812795 0.691746" mass="0.12541" diaginertia="3.57685e-05 2.46485e-05 2.14424e-05"/>
          <joint name="left_pinky_CMC" pos="0 0 0" axis="0 0 1" range="0 0.2618" class="PCMC_joint"/>
          <geom type="mesh" contype="0" conaffinity="0" group="1" density="0" rgba="0.79216 0.81961 0.93333 1" mesh="left_pinky_MC_visual" name="left_pinky_MC_visual"/>
          <geom type="mesh" contype="1" conaffinity="1" group="3" rgba="0.79216 0.81961 0.93333 1" mesh="left_pinky_MC" name="left_pinky_MC"/>
          <body name="left_pinky_MCP_VL" pos="0.00836 0.0048 0" quat="0.499998 -0.5 0.5 0.500002">
            <inertial pos="4.8e-09 0.00086981 -3.6e-09" mass="0.001" diaginertia="2e-12 2e-12 2e-12"/>
            <joint name="left_pinky_MCP_FE" pos="0 0 0" axis="0 0 1" range="-0.17453293 1.5708" class="MCP_joint"/>
            <geom type="mesh" contype="0" conaffinity="0" group="1" density="0" rgba="0.79216 0.81961 0.93333 1" mesh="left_MCP_VL_visual" name="left_pinky_MCP_VL_visual"/>
            <geom type="mesh" contype="1" conaffinity="1" group="3" rgba="0.79216 0.81961 0.93333 1" mesh="MCP_VL" name="left_pinky_MCP_VL"/>
            <body name="left_pinky_PP" quat="0.707105 0.707108 0 0">
              <inertial pos="0.0243772 -1.00263e-06 0.000755901" quat="0.519877 0.479286 0.479204 0.519977" mass="0.04138" diaginertia="6.82371e-06 6.54097e-06 2.16753e-06"/>
              <joint name="left_pinky_MCP_AA" pos="0 0 0" axis="0 0 1" range="-0.3491 0.3491" class="MCP_joint"/>
              <geom type="mesh" contype="0" conaffinity="0" group="1" density="0" rgba="0.79216 0.81961 0.93333 1" mesh="left_PP_visual" name="left_pinky_PP_visual"/>
              <geom type="mesh" contype="1" conaffinity="1" group="3" rgba="0.79216 0.81961 0.93333 1" mesh="left_PP" name="left_pinky_PP"/>
              <body name="left_sharpa_pinky_proximal_site" pos="0 0 0" quat="0 0.70710678 0.70710678 0">
                <site name="left_sharpa_pinky_proximal_site" group="4" size="0.002 0.002 0.002"/>
              </body>
              <body name="left_pinky_MP" pos="0.047 0 0" quat="0.707105 -0.707108 0 0">
                <inertial pos="0.015316 -0.00138561 6.27987e-08" quat="-0.0196259 0.706839 0.0195186 0.706832" mass="0.02509" diaginertia="2.28516e-06 2.26758e-06 9.99868e-07"/>
                <joint name="left_pinky_PIP" pos="0 0 0" axis="0 0 1" range="0 1.7453" class="PIP_joint"/>
                <geom type="mesh" contype="0" conaffinity="0" group="1" density="0" rgba="0.79216 0.81961 0.93333 1" mesh="left_MP_visual" name="left_pinky_MP_visual"/>
                <geom type="mesh" contype="1" conaffinity="1" group="3" rgba="0.79216 0.81961 0.93333 1" mesh="left_MP" name="left_pinky_MP"/>
                <body name="left_sharpa_pinky_intermediate_site" pos="0 0 0" quat="0.5 0.5 0.5 -0.5">
                  <site name="left_sharpa_pinky_intermediate_site" group="4" size="0.002 0.002 0.002"/>
                </body>
                <body name="left_pinky_DP" pos="0.0315 0 0">
                  <inertial pos="0.00931208 -0.00769378 0.000111984" quat="0.643953 0.245771 -0.649317 0.321417" mass="0.005102" diaginertia="4.23686e-07 3.85387e-07 1.37226e-07"/>
                  <joint name="left_pinky_DIP" pos="0 0 0" axis="0 0 1" range="0 1.3963" class="DIP_joint"/>
                  <geom type="mesh" contype="0" conaffinity="0" group="1" density="0" rgba="0.79216 0.81961 0.93333 1" mesh="left_DP_visual" name="left_pinky_DP_visual"/>
                  <geom type="mesh" contype="1" conaffinity="1" group="3" rgba="0.79216 0.81961 0.93333 1" mesh="left_DP" name="left_pinky_DP"/>
                  <geom quat="0.5 0.5 -0.5 0.5" type="mesh" contype="0" conaffinity="0" group="1" density="0" rgba="0.2 1 0.2 1" solref="0.06 0.9" mesh="elastomer" name="left_pinky_elastomer_visual"/>
                  <geom quat="0.5 0.5 -0.5 0.5" contype="1" conaffinity="1" group="3" type="mesh" rgba="0.2 1 0.2 1" mesh="elastomer" name="left_pinky_elastomer"/>
                  <body name="left_sharpa_pinky_distal_site" pos="0 0 0" quat="0.5 0.5 0.5 -0.5">
                    <site name="left_sharpa_pinky_distal_site" group="4" size="0.002 0.002 0.002"/>
                  </body>
                  <body name="left_sharpa_pinky_tip_site" pos="0.027 0 0" quat="0.5 0.5 0.5 -0.5">
                    <site name="left_sharpa_pinky_tip_site" group="4" size="0.002 0.002 0.002"/>
                  </body>
                </body>
              </body>
            </body>
          </body>
        </body>
      </body>
    </body>
    <body mocap="true" name="right-wrist" pos="-0.48 -0.15 1.1" quat="0 0.7071 0.7071 0">
      <site pos="0 0 0" name="right-wrist-site-mocap" rgba="0.658 0.411 0.75 1" size="0.002 0.002 0.002" group="5"/>
    </body>
    <body mocap="true" name="right-thumb-tip" pos="-0.39 -0.28 1.117" quat="0.2706 0.6533 0.2706 -0.6533">
      <site pos="0 0 0" name="right-thumb-tip-site-mocap" rgba="0.658 0.411 0.75 1" size="0.002 0.002 0.002" group="5"/>
    </body>
    <body mocap="true" name="right-index-finger-tip" pos="-0.3 -0.18 1.1" quat="0 0.7071 0.7071 0">
      <site pos="0 0 0" name="right-index-finger-tip-site-mocap" rgba="0.658 0.411 0.75 1" size="0.002 0.002 0.002" group="5"/>
    </body>
    <body mocap="true" name="right-middle-finger-tip" pos="-0.29500000000000004 -0.16 1.1" quat="0 0.7071 0.7071 0">
      <site pos="0 0 0" name="right-middle-finger-tip-site-mocap" rgba="0.658 0.411 0.75 1" size="0.002 0.002 0.002" group="5"/>
    </body>
    <body mocap="true" name="right-ring-finger-tip" pos="-0.301 -0.13999999999999999 1.1" quat="0 0.7071 0.7071 0">
      <site pos="0 0 0" name="right-ring-finger-tip-site-mocap" rgba="0.658 0.411 0.75 1" size="0.002 0.002 0.002" group="5"/>
    </body>
    <body mocap="true" name="right-pinky-finger-tip" pos="-0.307 -0.12 1.1" quat="0 0.7071 0.7071 0">
      <site pos="0 0 0" name="right-pinky-finger-tip-site-mocap" rgba="0.658 0.411 0.75 1" size="0.002 0.002 0.002" group="5"/>
    </body>
    <body mocap="true" name="left-wrist" pos="-0.48 0.15 1.1" quat="0 0.7071 0.7071 0">
      <site pos="0 0 0" name="left-wrist-site-mocap" rgba="0.658 0.411 0.75 1" size="0.002 0.002 0.002" group="5"/>
    </body>
    <body mocap="true" name="left-thumb-tip" pos="-0.39 0.28 1.117" quat="0.6533 -0.2706 -0.6533 -0.2706">
      <site pos="0 0 0" name="left-thumb-tip-site-mocap" rgba="0.658 0.411 0.75 1" size="0.002 0.002 0.002" group="5"/>
    </body>
    <body mocap="true" name="left-index-finger-tip" pos="-0.3 0.18 1.1" quat="0 0.7071 0.7071 0">
      <site pos="0 0 0" name="left-index-finger-tip-site-mocap" rgba="0.658 0.411 0.75 1" size="0.002 0.002 0.002" group="5"/>
    </body>
    <body mocap="true" name="left-middle-finger-tip" pos="-0.29500000000000004 0.16 1.1" quat="0 0.7071 0.7071 0">
      <site pos="0 0 0" name="left-middle-finger-tip-site-mocap" rgba="0.658 0.411 0.75 1" size="0.002 0.002 0.002" group="5"/>
    </body>
    <body mocap="true" name="left-ring-finger-tip" pos="-0.301 0.13999999999999999 1.1" quat="0 0.7071 0.7071 0">
      <site pos="0 0 0" name="left-ring-finger-tip-site-mocap" rgba="0.658 0.411 0.75 1" size="0.002 0.002 0.002" group="5"/>
    </body>
    <body mocap="true" name="left-pinky-finger-tip" pos="-0.307 0.12 1.1" quat="0 0.7071 0.7071 0">
      <site pos="0 0 0" name="left-pinky-finger-tip-site-mocap" rgba="0.658 0.411 0.75 1" size="0.002 0.002 0.002" group="5"/>
    </body>
  </worldbody>
  <equality>
    <weld site1="right-wrist-site-mocap" site2="sharpa_palm_site"/>
    <weld site1="right-thumb-tip-site-mocap" site2="sharpa_thumb_tip_site"/>
    <weld site1="right-index-finger-tip-site-mocap" site2="sharpa_index_tip_site"/>
    <weld site1="right-middle-finger-tip-site-mocap" site2="sharpa_middle_tip_site"/>
    <weld site1="right-ring-finger-tip-site-mocap" site2="sharpa_ring_tip_site"/>
    <weld site1="right-pinky-finger-tip-site-mocap" site2="sharpa_pinky_tip_site"/>
    <weld site1="left-wrist-site-mocap" site2="left_sharpa_palm_site"/>
    <weld site1="left-thumb-tip-site-mocap" site2="left_sharpa_thumb_tip_site"/>
    <weld site1="left-index-finger-tip-site-mocap" site2="left_sharpa_index_tip_site"/>
    <weld site1="left-middle-finger-tip-site-mocap" site2="left_sharpa_middle_tip_site"/>
    <weld site1="left-ring-finger-tip-site-mocap" site2="left_sharpa_ring_tip_site"/>
    <weld site1="left-pinky-finger-tip-site-mocap" site2="left_sharpa_pinky_tip_site"/>
  </equality>
  <actuator>
    <position name="right_thumb_CMC_FE_ctrl" joint="right_thumb_CMC_FE" kp="6.95" dampratio="0.9" inheritrange="1.0"/>
    <position name="right_thumb_CMC_AA_ctrl" joint="right_thumb_CMC_AA" kp="13.2" dampratio="0.9" inheritrange="1.0"/>
    <position name="right_thumb_MCP_FE_ctrl" joint="right_thumb_MCP_FE" kp="4.76" dampratio="0.9" inheritrange="1.0"/>
    <position name="right_thumb_MCP_AA_ctrl" joint="right_thumb_MCP_AA" kp="6.62" dampratio="0.9" inheritrange="1.0"/>
    <position name="right_thumb_IP_ctrl" joint="right_thumb_IP" kp="0.9" dampratio="0.9" inheritrange="1.0"/>
    <position name="right_index_MCP_FE_ctrl" joint="right_index_MCP_FE" kp="4.76" dampratio="0.9" inheritrange="1.0"/>
    <position name="right_index_MCP_AA_ctrl" joint="right_index_MCP_AA" kp="6.62" dampratio="0.9" inheritrange="1.0"/>
    <position name="right_index_PIP_ctrl" joint="right_index_PIP" kp="0.9" dampratio="0.9" inheritrange="1.0"/>
    <position name="right_index_DIP_ctrl" joint="right_index_DIP" kp="0.9" dampratio="0.9" inheritrange="1.0"/>
    <position name="right_middle_MCP_FE_ctrl" joint="right_middle_MCP_FE" kp="4.76" dampratio="0.9" inheritrange="1.0"/>
    <position name="right_middle_MCP_AA_ctrl" joint="right_middle_MCP_AA" kp="6.62" dampratio="0.9" inheritrange="1.0"/>
    <position name="right_middle_PIP_ctrl" joint="right_middle_PIP" kp="0.9" dampratio="0.9" inheritrange="1.0"/>
    <position name="right_middle_DIP_ctrl" joint="right_middle_DIP" kp="0.9" dampratio="0.9" inheritrange="1.0"/>
    <position name="right_ring_MCP_FE_ctrl" joint="right_ring_MCP_FE" kp="4.76" dampratio="0.9" inheritrange="1.0"/>
    <position name="right_ring_MCP_AA_ctrl" joint="right_ring_MCP_AA" kp="6.62" dampratio="0.9" inheritrange="1.0"/>
    <position name="right_ring_PIP_ctrl" joint="right_ring_PIP" kp="0.9" dampratio="0.9" inheritrange="1.0"/>
    <position name="right_ring_DIP_ctrl" joint="right_ring_DIP" kp="0.9" dampratio="0.9" inheritrange="1.0"/>
    <position name="right_pinky_CMC_ctrl" joint="right_pinky_CMC" kp="1.38" dampratio="0.9" inheritrange="1.0"/>
    <position name="right_pinky_MCP_FE_ctrl" joint="right_pinky_MCP_FE" kp="4.76" dampratio="0.9" inheritrange="1.0"/>
    <position name="right_pinky_MCP_AA_ctrl" joint="right_pinky_MCP_AA" kp="6.62" dampratio="0.9" inheritrange="1.0"/>
    <position name="right_pinky_PIP_ctrl" joint="right_pinky_PIP" kp="0.9" dampratio="0.9" inheritrange="1.0"/>
    <position name="right_pinky_DIP_ctrl" joint="right_pinky_DIP" kp="0.9" dampratio="0.9" inheritrange="1.0"/>
    <position name="left_thumb_CMC_FE_ctrl" joint="left_thumb_CMC_FE" kp="6.95" dampratio="0.9" inheritrange="1.0"/>
    <position name="left_thumb_CMC_AA_ctrl" joint="left_thumb_CMC_AA" kp="13.2" dampratio="0.9" inheritrange="1.0"/>
    <position name="left_thumb_MCP_FE_ctrl" joint="left_thumb_MCP_FE" kp="4.76" dampratio="0.9" inheritrange="1.0"/>
    <position name="left_thumb_MCP_AA_ctrl" joint="left_thumb_MCP_AA" kp="6.62" dampratio="0.9" inheritrange="1.0"/>
    <position name="left_thumb_IP_ctrl" joint="left_thumb_IP" kp="0.9" dampratio="0.9" inheritrange="1.0"/>
    <position name="left_index_MCP_FE_ctrl" joint="left_index_MCP_FE" kp="4.76" dampratio="0.9" inheritrange="1.0"/>
    <position name="left_index_MCP_AA_ctrl" joint="left_index_MCP_AA" kp="6.62" dampratio="0.9" inheritrange="1.0"/>
    <position name="left_index_PIP_ctrl" joint="left_index_PIP" kp="0.9" dampratio="0.9" inheritrange="1.0"/>
    <position name="left_index_DIP_ctrl" joint="left_index_DIP" kp="0.9" dampratio="0.9" inheritrange="1.0"/>
    <position name="left_middle_MCP_FE_ctrl" joint="left_middle_MCP_FE" kp="4.76" dampratio="0.9" inheritrange="1.0"/>
    <position name="left_middle_MCP_AA_ctrl" joint="left_middle_MCP_AA" kp="6.62" dampratio="0.9" inheritrange="1.0"/>
    <position name="left_middle_PIP_ctrl" joint="left_middle_PIP" kp="0.9" dampratio="0.9" inheritrange="1.0"/>
    <position name="left_middle_DIP_ctrl" joint="left_middle_DIP" kp="0.9" dampratio="0.9" inheritrange="1.0"/>
    <position name="left_ring_MCP_FE_ctrl" joint="left_ring_MCP_FE" kp="4.76" dampratio="0.9" inheritrange="1.0"/>
    <position name="left_ring_MCP_AA_ctrl" joint="left_ring_MCP_AA" kp="6.62" dampratio="0.9" inheritrange="1.0"/>
    <position name="left_ring_PIP_ctrl" joint="left_ring_PIP" kp="0.9" dampratio="0.9" inheritrange="1.0"/>
    <position name="left_ring_DIP_ctrl" joint="left_ring_DIP" kp="0.9" dampratio="0.9" inheritrange="1.0"/>
    <position name="left_pinky_CMC_ctrl" joint="left_pinky_CMC" kp="1.38" dampratio="0.9" inheritrange="1.0"/>
    <position name="left_pinky_MCP_FE_ctrl" joint="left_pinky_MCP_FE" kp="4.76" dampratio="0.9" inheritrange="1.0"/>
    <position name="left_pinky_MCP_AA_ctrl" joint="left_pinky_MCP_AA" kp="6.62" dampratio="0.9" inheritrange="1.0"/>
    <position name="left_pinky_PIP_ctrl" joint="left_pinky_PIP" kp="0.9" dampratio="0.9" inheritrange="1.0"/>
    <position name="left_pinky_DIP_ctrl" joint="left_pinky_DIP" kp="0.9" dampratio="0.9" inheritrange="1.0"/>
  </actuator>
  <contact>
    <exclude body1="right_hand_C_MC" body2="right_thumb_CMC_VL"/>
    <exclude body1="right_hand_C_MC" body2="right_hand_C_MC"/>
    <exclude body1="right_hand_C_MC" body2="right_thumb_MC"/>
    <exclude body1="right_thumb_MC" body2="right_thumb_MCP_VL"/>
    <exclude body1="right_thumb_MC" body2="right_thumb_PP"/>
    <exclude body1="right_thumb_MCP_VL" body2="right_thumb_PP"/>
    <exclude body1="right_thumb_PP" body2="right_thumb_DP"/>
    <exclude body1="right_hand_C_MC" body2="right_index_MCP_VL"/>
    <exclude body1="right_hand_C_MC" body2="right_index_PP"/>
    <exclude body1="right_index_MCP_VL" body2="right_index_PP"/>
    <exclude body1="right_index_PP" body2="right_index_MP"/>
    <exclude body1="right_index_MP" body2="right_index_DP"/>
    <exclude body1="right_hand_C_MC" body2="right_middle_MCP_VL"/>
    <exclude body1="right_hand_C_MC" body2="right_middle_PP"/>
    <exclude body1="right_middle_MCP_VL" body2="right_middle_PP"/>
    <exclude body1="right_middle_PP" body2="right_middle_MP"/>
    <exclude body1="right_middle_MP" body2="right_middle_DP"/>
    <exclude body1="right_hand_C_MC" body2="right_ring_MCP_VL"/>
    <exclude body1="right_hand_C_MC" body2="right_ring_PP"/>
    <exclude body1="right_ring_MCP_VL" body2="right_ring_PP"/>
    <exclude body1="right_ring_PP" body2="right_ring_MP"/>
    <exclude body1="right_ring_MP" body2="right_ring_DP"/>
    <exclude body1="right_hand_C_MC" body2="right_pinky_MC"/>
    <exclude body1="right_pinky_MC" body2="right_pinky_MCP_VL"/>
    <exclude body1="right_pinky_MC" body2="right_pinky_PP"/>
    <exclude body1="right_pinky_MCP_VL" body2="right_pinky_PP"/>
    <exclude body1="right_pinky_PP" body2="right_pinky_MP"/>
    <exclude body1="right_pinky_MP" body2="right_pinky_DP"/>
    <exclude body1="left_hand_C_MC" body2="left_thumb_CMC_VL"/>
    <exclude body1="left_hand_C_MC" body2="left_hand_C_MC"/>
    <exclude body1="left_hand_C_MC" body2="left_thumb_MC"/>
    <exclude body1="left_thumb_MC" body2="left_thumb_MCP_VL"/>
    <exclude body1="left_thumb_MC" body2="left_thumb_PP"/>
    <exclude body1="left_thumb_MCP_VL" body2="left_thumb_PP"/>
    <exclude body1="left_thumb_PP" body2="left_thumb_DP"/>
    <exclude body1="left_hand_C_MC" body2="left_index_MCP_VL"/>
    <exclude body1="left_hand_C_MC" body2="left_index_PP"/>
    <exclude body1="left_index_MCP_VL" body2="left_index_PP"/>
    <exclude body1="left_index_PP" body2="left_index_MP"/>
    <exclude body1="left_index_MP" body2="left_index_DP"/>
    <exclude body1="left_hand_C_MC" body2="left_middle_MCP_VL"/>
    <exclude body1="left_hand_C_MC" body2="left_middle_PP"/>
    <exclude body1="left_middle_MCP_VL" body2="left_middle_PP"/>
    <exclude body1="left_middle_PP" body2="left_middle_MP"/>
    <exclude body1="left_middle_MP" body2="left_middle_DP"/>
    <exclude body1="left_hand_C_MC" body2="left_ring_MCP_VL"/>
    <exclude body1="left_hand_C_MC" body2="left_ring_PP"/>
    <exclude body1="left_ring_MCP_VL" body2="left_ring_PP"/>
    <exclude body1="left_ring_PP" body2="left_ring_MP"/>
    <exclude body1="left_ring_MP" body2="left_ring_DP"/>
    <exclude body1="left_hand_C_MC" body2="left_pinky_MC"/>
    <exclude body1="left_pinky_MC" body2="left_pinky_MCP_VL"/>
    <exclude body1="left_pinky_MC" body2="left_pinky_PP"/>
    <exclude body1="left_pinky_MCP_VL" body2="left_pinky_PP"/>
    <exclude body1="left_pinky_PP" body2="left_pinky_MP"/>
    <exclude body1="left_pinky_MP" body2="left_pinky_DP"/>
  </contact>
</mujoco>